<?xml version="1.0" ?>
<sdf version="1.6">
  <model name="my_robot">
    <static>false</static>
    
    <!-- Chassis -->
    <link name="chassis">
      <pose>0 0 0.5 0 0 0</pose> <!-- Position the chassis above the ground -->
      <inertial>
        <mass>10</mass>
        <inertia>
          <ixx>0.5</ixx>
          <iyy>0.5</iyy>
          <izz>0.5</izz>
        </inertia>
      </inertial>
      <collision name="chassis_collision">
        <geometry>
          <box>
            <size>1.0 0.5 0.2</size> <!-- Chassis size: 1m length, 0.5m width, 0.2m height -->
          </box>
        </geometry>
      </collision>
      <visual name="chassis_visual">
        <geometry>
          <box>
            <size>1.0 0.5 0.2</size>
          </box>
        </geometry>
        <material>
          <ambient>0.5 0.5 0.5 1</ambient>
          <diffuse>0.5 0.5 0.5 1</diffuse>
        </material>
      </visual>
    </link>

    <!-- Left Wheel -->
    <link name="left_wheel">
      <pose>-0.4 0.3 0.1 0 0 0</pose> <!-- Adjust position for left wheel -->
      <inertial>
        <mass>1.0</mass>
      </inertial>
      <collision name="left_wheel_collision">
        <geometry>
          <cylinder>
            <radius>0.1</radius>
            <length>0.05</length>
          </cylinder>
        </geometry>
      </collision>
      <visual name="left_wheel_visual">
        <geometry>
          <cylinder>
            <radius>0.1</radius>
            <length>0.05</length>
          </cylinder>
        </geometry>
      </visual>
    </link>

    <!-- Right Wheel -->
    <link name="right_wheel">
      <pose>-0.4 -0.3 0.1 0 0 0</pose> <!-- Adjust position for right wheel -->
      <inertial>
        <mass>1.0</mass>
      </inertial>
      <collision name="right_wheel_collision">
        <geometry>
          <cylinder>
            <radius>0.1</radius>
            <length>0.05</length>
          </cylinder>
        </geometry>
      </collision>
      <visual name="right_wheel_visual">
        <geometry>
          <cylinder>
            <radius>0.1</radius>
            <length>0.05</length>
          </cylinder>
        </geometry>
      </visual>
    </link>

    <!-- Joints for the wheels -->
    <joint name="left_wheel_joint" type="revolute">
      <parent>chassis</parent>
      <child>left_wheel</child>
      <axis>
        <xyz>0 1 0</xyz>
        <limit>
          <lower>-1e16</lower>
          <upper>1e16</upper>
        </limit>
        <dynamics>
          <damping>0.1</damping>
        </dynamics>
      </axis>
    </joint>

    <joint name="right_wheel_joint" type="revolute">
      <parent>chassis</parent>
      <child>right_wheel</child>
      <axis>
        <xyz>0 1 0</xyz>
        <limit>
          <lower>-1e16</lower>
          <upper>1e16</upper>
        </limit>
        <dynamics>
          <damping>0.1</damping>
        </dynamics>
      </axis>
    </joint>

    <!-- Add a camera to the front -->
    <link name="camera_link">
      <pose>0.5 0 0.15 0 0 0</pose> <!-- Position the camera at the front -->
      <sensor name="camera" type="camera">
        <camera>
          <horizontal_fov>1.047</horizontal_fov>
          <image>
            <width>640</width>
            <height>480</height>
          </image>
          <clip>
            <near>0.1</near>
            <far>100</far>
          </clip>
        </camera>
      </sensor>
    </link>
  </model>
</sdf>
